<?xml version="1.0" encoding="utf-8"?>
<!--
This is the URDF model for the Self Built CNC Welding Mechanism for CNERC, HK PolyU.
15 July 2021, by Victor W H Wu.
Updated on 18 July 2021 to have all X, Y, and Z axes.
The Turn table is still needed to be put on and replace the tool0.
Updated on 19 July 2021, tool0 has been replaced with the Turn Table, Welding Torch, and Laser Scanner.
-->
<robot name="cncweld" xmlns:xacro="http://ros.org/wiki/xacro">

  <link name="world" />

<!--
  There are 2 rails for the X link. 
-->
  <link
    name="X_link">
    <visual>
      <origin
        xyz="0 0 0"
        rpy="0 0 0" />
      <geometry>
        <mesh
          filename="package://cnc_description/meshes/X_axis.STL" />
      </geometry>
      <material
        name="">
        <color
          rgba="0.792156862745098 0.819607843137255 0.933333333333333 1" />
      </material>
    </visual>
    <collision>
      <origin
        xyz="0 0 0"
        rpy="0 0 0" />
      <geometry>
        <mesh
          filename="package://cnc_description/meshes/X_axis.STL" />
      </geometry>
    </collision>
  </link>
<!--
  The World to X link Fixed Joint
-->
  <joint name="world_to_X_link" type="fixed">
    <parent link="world" />
    <child link="X_link" />
    <origin xyz="0.0 -0.1445 0.0" rpy="0.0 0.0 0.0" />
  </joint>

<!--
  The Y link
-->
  <link
    name="Y_link">
    <visual>
      <origin
        xyz="0.0 0.0 0.0"
        rpy="0 0 0" />
      <geometry>
        <mesh
          filename="package://cnc_description/meshes/Y_axis_assy.STL" />
      </geometry>
      <material
        name="">
        <color
          rgba="0.792156862745098 0.819607843137255 0.933333333333333 1" />
      </material>
    </visual>
    <collision>
      <origin
        xyz="0.0 0.0 0.0"
        rpy="0 0 0" />
      <geometry>
        <mesh
          filename="package://cnc_description/meshes/Y_axis_assy.STL" />
      </geometry>
    </collision>
  </link>

<!--
  The X link to Y link Prismatic Joint
-->
  <joint
    name="X_link_Y_link_joint"
    type="prismatic">
    <origin
      xyz="0.0 0.0 0.0" rpy="0.0 0.0 0.0" />
    <parent
      link="X_link" />
    <child
      link="Y_link" />
    <axis  xyz="1 0 0"/>
    <limit effort="1000.0" lower="0.0" upper="0.7" velocity="0.05"/>
  </joint>

<!--
  The Z link
-->
  <link
    name="Z_link">
    <visual>
      <origin
        xyz="0.0 0.0 0.0"
        rpy="0 0 0" />
      <geometry>
        <mesh
          filename="package://cnc_description/meshes/Z_axis_assy.STL" />
      </geometry>
      <material
        name="">
        <color
          rgba="0.792156862745098 0.819607843137255 0.933333333333333 1" />
      </material>
    </visual>
    <collision>
      <origin
        xyz="0.0 0.0 0.0"
        rpy="0 0 0" />
      <geometry>
        <mesh
          filename="package://cnc_description/meshes/Z_axis_assy.STL" />
      </geometry>
    </collision>
  </link>

<!--
  The Y link to Z link Prismatic Joint
-->
  <joint
    name="Y_link_Z_link_joint"
    type="prismatic">
    <origin
      xyz="0.0 0.0 0.0" rpy="0.0 0.0 0.0" />
    <parent
      link="Y_link" />
    <child
      link="Z_link" />
    <limit effort="1000.0" lower="0.0" upper="0.21" velocity="0.05"/>
    <axis  xyz="0 1 0"/>
  </joint>

<!--
  The Slide link on the Z link.
  Usually the last link is the tool0 and the End Effector will be
  fixed on it.
-->
  <link
    name="tool0">
    <visual>
      <origin
        xyz="0.0 0.0 0.0"
        rpy="0 0 0" />
      <geometry>
        <mesh
          filename="package://cnc_description/meshes/tool0.STL" />
      </geometry>
      <material
        name="">
        <color
          rgba="0.792156862745098 0.819607843137255 0.933333333333333 1" />
      </material>
    </visual>
    <collision>
      <origin
        xyz="0.0 0.0 0.0"
        rpy="0 0 0" />
      <geometry>
        <mesh
          filename="package://cnc_description/meshes/tool0.STL" />
      </geometry>
    </collision>
  </link>

<!--
  The Z link to tool0 Prismatic Joint
-->
  <joint
    name="Z_link_tool0_joint"
    type="prismatic">
<!--
    <origin xyz="0.045 0.0 0.0" rpy="0.0 0.0 0.0" />
-->
    <origin xyz="0.31 0.046 0.0" rpy="0.0 0.0 0.0" />
    <parent
      link="Z_link" />
    <child
      link="tool0" />
    <limit effort="1000.0" lower="0.0" upper="0.086" velocity="0.05"/>
    <axis  xyz="0 0 1"/>
  </joint>

</robot>
